<?xml version="1.0" encoding="UTF-8"?>
<!-- Generated by org.testng.reporters.JUnitXMLReporter -->
<testsuite ignored="0" hostname="DESKTOP-DKK5M0P" failures="2" tests="2" name="Standalone" time="25.383" errors="0" timestamp="2025-02-06T19:32:06 IST">
  <testcase classname="tests.Standalone" name="productOrder" time="15.512">
    <failure type="java.lang.AssertionError" message="expected [THANKYOU FOR THE ORDERr.] but found [THANKYOU FOR THE ORDER.]">
      <![CDATA[java.lang.AssertionError: expected [THANKYOU FOR THE ORDERr.] but found [THANKYOU FOR THE ORDER.]
at tests.Standalone.productOrder(Standalone.java:35)
at java.base/java.util.ArrayList.forEach(ArrayList.java:1597)
at java.base/java.util.concurrent.FutureTask.run(FutureTask.java:317)
at java.base/java.util.concurrent.ThreadPoolExecutor.runWorker(ThreadPoolExecutor.java:1144)
at java.base/java.util.concurrent.ThreadPoolExecutor$Worker.run(ThreadPoolExecutor.java:642)
at java.base/java.lang.Thread.run(Thread.java:1575)
... Removed 22 stack frames]]>
    </failure>
  </testcase> <!-- productOrder -->
  <testcase classname="tests.Standalone" name="productOrder" time="25.169">
    <failure type="java.lang.NullPointerException">
      <![CDATA[java.lang.NullPointerException
at java.base/java.io.File.<init>(File.java:278)
at testComponents.BaseTest.getScreenshot(BaseTest.java:85)
at testComponents.Listeners.onTestFailure(Listeners.java:42)
at java.base/java.util.ArrayList.forEach(ArrayList.java:1597)
at java.base/java.util.concurrent.FutureTask.run(FutureTask.java:317)
at java.base/java.util.concurrent.ThreadPoolExecutor.runWorker(ThreadPoolExecutor.java:1144)
at java.base/java.util.concurrent.ThreadPoolExecutor$Worker.run(ThreadPoolExecutor.java:642)
at java.base/java.lang.Thread.run(Thread.java:1575)
... Removed 15 stack frames]]>
    </failure>
  </testcase> <!-- productOrder -->
</testsuite> <!-- Standalone -->
